<?xml version="1.0" encoding="utf-8"?>
<!-- This URDF was automatically created by SolidWorks to URDF Exporter! Originally created by Stephen Brawner (brawner@gmail.com) 
     Commit Version: 1.6.0-1-g15f4949  Build Version: 1.6.7594.29634
     For more information, please see http://wiki.ros.org/sw_urdf_exporter -->
<robot
  name="ar4">
  <link
    name="link0">
    <inertial>
      <origin
        xyz="-9.55703382238532E-06 -0.10623408006537 0.0394896874690768"
        rpy="0 0 0" />
      <mass
        value="1.04125676285366" />
      <inertia
        ixx="0.00252637092686072"
        ixy="-7.39591996895186E-07"
        ixz="2.23138573999412E-07"
        iyy="0.00193066965961962"
        iyz="8.26871545820155E-05"
        izz="0.00402446011690346" />
    </inertial>
    <visual>
      <origin
        xyz="0 0 0"
        rpy="0 0 0" />
      <geometry>
        <mesh
          filename="package://ar4/meshes/link0.STL" />
      </geometry>
      <material
        name="">
        <color
          rgba="0.792156862745098 0.819607843137255 0.933333333333333 1" />
      </material>
    </visual>
    <collision>
      <origin
        xyz="0 0 0"
        rpy="0 0 0" />
      <geometry>
        <mesh
          filename="package://ar4/meshes/link0.STL" />
      </geometry>
    </collision>
  </link>
  <link
    name="link1">
    <inertial>
      <origin
        xyz="0.0150800198577554 0.0445528735922516 0.13256960216992"
        rpy="0 0 0" />
      <mass
        value="0.923841799716981" />
      <inertia
        ixx="0.0007897051646221"
        ixy="-4.08541540146023E-06"
        ixz="-2.24624377128789E-06"
        iyy="0.000595147841944496"
        iyz="-3.60934039310079E-05"
        izz="0.00055472183280157" />
    </inertial>
    <visual>
      <origin
        xyz="0 0 0"
        rpy="0 0 0" />
      <geometry>
        <mesh
          filename="package://ar4/meshes/link1.STL" />
      </geometry>
      <material
        name="">
        <color
          rgba="0.792156862745098 0.819607843137255 0.933333333333333 1" />
      </material>
    </visual>
    <collision>
      <origin
        xyz="0 0 0"
        rpy="0 0 0" />
      <geometry>
        <mesh
          filename="package://ar4/meshes/link1.STL" />
      </geometry>
    </collision>
  </link>
  <joint
    name="J1"
    type="revolute">
    <origin
      xyz="0 0 0"
      rpy="0 0 0" />
    <parent
      link="link0" />
    <child
      link="link1" />
    <axis
      xyz="0 0 1" />
    <limit
      lower="-2.9671"
      upper="2.9671"
      effort="30"
      velocity="1.5" />
  </joint>
  <link
    name="link2">
    <inertial>
      <origin
        xyz="-0.00125941471613257 0.154033883248923 -0.0455187929174894"
        rpy="0 0 0" />
      <mass
        value="0.66602630598886" />
      <inertia
        ixx="0.00267577630675058"
        ixy="6.41480608085316E-06"
        ixz="-1.69534634342174E-06"
        iyy="0.00025868655873496"
        iyz="7.87457094638249E-09"
        izz="0.00285899027125921" />
    </inertial>
    <visual>
      <origin
        xyz="0 0 0"
        rpy="0 0 0" />
      <geometry>
        <mesh
          filename="package://ar4/meshes/link2.STL" />
      </geometry>
      <material
        name="">
        <color
          rgba="0.792156862745098 0.819607843137255 0.933333333333333 1" />
      </material>
    </visual>
    <collision>
      <origin
        xyz="0 0 0"
        rpy="0 0 0" />
      <geometry>
        <mesh
          filename="package://ar4/meshes/link2.STL" />
      </geometry>
    </collision>
  </link>
  <joint
    name="J2"
    type="revolute">
    <origin
      xyz="0 0.064146 0.16978"
      rpy="1.5708 0 1.5708" />
    <parent
      link="link1" />
    <child
      link="link2" />
    <axis
      xyz="0 0 1" />
    <limit
      lower="-1.3"
      upper="0.819"
      effort="30"
      velocity="1.5" />
  </joint>
  <link
    name="link3">
    <inertial>
      <origin
        xyz="-0.0188644038321781 0.0153818252284461 -0.00276625260042082"
        rpy="0 0 0" />
      <mass
        value="0.261165234951801" />
      <inertia
        ixx="0.000237067978869073"
        ixy="-4.00760539434471E-07"
        ixz="-6.1731908672183E-08"
        iyy="7.22899870112546E-05"
        iyz="-2.20781892943381E-06"
        izz="0.000228199256429616" />
    </inertial>
    <visual>
      <origin
        xyz="0 0 0"
        rpy="0 0 0" />
      <geometry>
        <mesh
          filename="package://ar4/meshes/link3.STL" />
      </geometry>
      <material
        name="">
        <color
          rgba="0.792156862745098 0.819607843137255 0.933333333333333 1" />
      </material>
    </visual>
    <collision>
      <origin
        xyz="0 0 0"
        rpy="0 0 0" />
      <geometry>
        <mesh
          filename="package://ar4/meshes/link3.STL" />
      </geometry>
    </collision>
  </link>
  <joint
    name="J3"
    type="revolute">
    <origin
      xyz="0 0.305 0"
      rpy="0 0 1.5708" />
    <parent
      link="link2" />
    <child
      link="link3" />
    <axis
      xyz="0 0 1" />
    <limit
      lower="-1.22"
      upper="1.5533"
      effort="30"
      velocity="1.5" />
  </joint>
  <link
    name="link4">
    <inertial>
      <origin
        xyz="0.00161364943981701 0.00237681766725436 0.127854796290858"
        rpy="0 0 0" />
      <mass
        value="0.253026340437627" />
      <inertia
        ixx="0.000464456616828757"
        ixy="2.99669439325788E-06"
        ixz="1.26520712831484E-05"
        iyy="0.000518437160459873"
        iyz="-5.33184339348515E-06"
        izz="9.40163461807407E-05" />
    </inertial>
    <visual>
      <origin
        xyz="0 0 0"
        rpy="0 0 0" />
      <geometry>
        <mesh
          filename="package://ar4/meshes/link4.STL" />
      </geometry>
      <material
        name="">
        <color
          rgba="0.792156862745098 0.819607843137255 0.933333333333333 1" />
      </material>
    </visual>
    <collision>
      <origin
        xyz="0 0 0"
        rpy="0 0 0" />
      <geometry>
        <mesh
          filename="package://ar4/meshes/link4.STL" />
      </geometry>
    </collision>
  </link>
  <joint
    name="J4"
    type="revolute">
    <origin
      xyz="0 0 0"
      rpy="1.5708 0 0" />
    <parent
      link="link3" />
    <child
      link="link4" />
    <axis
      xyz="0 0 1" />
    <limit
      lower="-1.57"
      upper="1.57"
      effort="30"
      velocity="1.5" />
  </joint>
  <link
    name="link5">
    <inertial>
      <origin
        xyz="-1.41334599429443E-05 0.00976082845031662 -0.00194066689986005"
        rpy="0 0 0" />
      <mass
        value="0.107166714100713" />
      <inertia
        ixx="1.78630269441855E-05"
        ixy="3.2974342072469E-09"
        ixz="7.50285260645335E-09"
        iyy="2.02818075683975E-05"
        iyz="-4.85086582511436E-09"
        izz="2.05310559908488E-05" />
    </inertial>
    <visual>
      <origin
        xyz="0 0 0"
        rpy="0 0 0" />
      <geometry>
        <mesh
          filename="package://ar4/meshes/link5.STL" />
      </geometry>
      <material
        name="">
        <color
          rgba="0.792156862745098 0.819607843137255 0.933333333333333 1" />
      </material>
    </visual>
    <collision>
      <origin
        xyz="0 0 0"
        rpy="0 0 0" />
      <geometry>
        <mesh
          filename="package://ar4/meshes/link5.STL" />
      </geometry>
    </collision>
  </link>
  <joint
    name="J5"
    type="revolute">
    <origin
      xyz="0 0 0.22234"
      rpy="-1.5708 0 0" />
    <parent
      link="link4" />
    <child
      link="link5" />
    <axis
      xyz="0 0 1" />
    <limit
      lower="-2"
      upper="0.6"
      effort="30"
      velocity="1.5" />
  </joint>
  <link
    name="link6">
    <inertial>
      <origin
        xyz="7.10235648071489E-10 1.11998347598837E-05 0.0333288994602314"
        rpy="0 0 0" />
      <mass
        value="0.0221921177466817" />
      <inertia
        ixx="3.06252645528352E-06"
        ixy="-6.73269671915162E-14"
        ixz="6.33716482111209E-09"
        iyy="2.15188709657542E-06"
        iyz="-4.03279540843088E-15"
        izz="4.12314767129102E-06" />
    </inertial>
    <visual>
      <origin
        xyz="0 0 0"
        rpy="0 0 0" />
      <geometry>
        <mesh
          filename="package://ar4/meshes/link6.STL" />
      </geometry>
      <material
        name="">
        <color
          rgba="0.792156862745098 0.819607843137255 0.933333333333333 1" />
      </material>
    </visual>
    <collision>
      <origin
        xyz="0 0 0"
        rpy="0 0 0" />
      <geometry>
        <mesh
          filename="package://ar4/meshes/link6.STL" />
      </geometry>
    </collision>
  </link>
  <joint
    name="J6"
    type="revolute">
    <origin
      xyz="0 0 0"
      rpy="1.5708 0 0" />
    <parent
      link="link5" />
    <child
      link="link6" />
    <axis
      xyz="0 0 -1" />
    <limit
      lower="-2.7053"
      upper="2.7053"
      effort="30"
      velocity="1.5" />
  </joint>
  <link
    name="Endpoint">
    <inertial>
      <origin
        xyz="0 -1.79999999998523E-06 0"
        rpy="0 0 0" />
      <mass
        value="0.000113097335529233" />
      <inertia
        ixx="4.07150407905237E-10"
        ixy="0"
        ixz="4.57896197274352E-59"
        iyy="4.07150407905237E-10"
        iyz="0"
        izz="4.07150407905237E-10" />
    </inertial>
    <visual>
      <origin
        xyz="0 0 0"
        rpy="0 0 0" />
      <geometry>
        <mesh
          filename="package://ar4/meshes/Endpoint.STL" />
      </geometry>
      <material
        name="">
        <color
          rgba="0.792156862745098 0.819607843137255 0.933333333333333 1" />
      </material>
    </visual>
    <collision>
      <origin
        xyz="0 0 0"
        rpy="0 0 0" />
      <geometry>
        <mesh
          filename="package://ar4/meshes/Endpoint.STL" />
      </geometry>
    </collision>
  </link>
  <joint
    name="Endpoint"
    type="fixed">
    <origin
      xyz="0 0 0.0659"
      rpy="0 0 0" />
    <parent
      link="link6" />
    <child
      link="Endpoint" />
    <axis
      xyz="0 0 0" />
  </joint>
</robot>